Workbook

Sheet Resumen
A1: Aromas del Valle — Resumen de la evaluación económica
A2: Todos los valores salen de las hojas de cálculo. Para cambiar un supuesto, edita la hoja Supuestos.
A4: VPN a TMAR real 16 % (S/) | B4: Pesimista | C4: Base | D4: Optimista | E4: VPN esperado
A5: Fase 1 (maquinaria, empaque, online, B2B) | B5: =Flujo_Pesimista!B80 -> -139467.55 | C5: =Flujo_Base!B80 -> 117319.82 | D5: =Flujo_Optimista!B80 -> 430319.34 | E5: =SUMPRODUCT(B5:D5,Supuestos!$C$85:$E$85) -> 131372.86
A6: Tienda Lima | B6: =Flujo_Pesimista!B81 -> -310886.64 | C6: =Flujo_Base!B81 -> -140865.6 | D6: =Flujo_Optimista!B81 -> 28858.167 | E6: =SUMPRODUCT(B6:D6,Supuestos!$C$85:$E$85) -> -140939.92
A7: Tienda Arequipa | B7: =Flujo_Pesimista!B82 -> -178455.17 | C7: =Flujo_Base!B82 -> -53812.709 | D7: =Flujo_Optimista!B82 -> 59336.471 | E7: =SUMPRODUCT(B7:D7,Supuestos!$C$85:$E$85) -> -56686.028
A8: Tiendas (Fase 2) | B8: =Flujo_Pesimista!B83 -> -489341.8 | C8: =Flujo_Base!B83 -> -194678.31 | D8: =Flujo_Optimista!B83 -> 88194.638 | E8: =SUMPRODUCT(B8:D8,Supuestos!$C$85:$E$85) -> -197625.95
A9: Proyecto completo | B9: =Flujo_Pesimista!B84 -> -628809.35 | C9: =Flujo_Base!B84 -> -77358.488 | D9: =Flujo_Optimista!B84 -> 518513.98 | E9: =SUMPRODUCT(B9:D9,Supuestos!$C$85:$E$85) -> -66253.085
A10: Proyecto completo — financiero (préstamo S/ 480 mil) | B10: =Flujo_Pesimista!B85 -> -547968.96 | C10: =Flujo_Base!B85 -> 3481.9023 | D10: =Flujo_Optimista!B85 -> 599354.37 | E10: =SUMPRODUCT(B10:D10,Supuestos!$C$85:$E$85) -> 14587.305
A11: Solo Fase 1 — financiero (préstamo S/ 260 mil) | B11: =Flujo_Pesimista!B86 -> -95679 | C11: =Flujo_Base!B86 -> 161108.37 | D11: =Flujo_Optimista!B86 -> 474107.89 | E11: =SUMPRODUCT(B11:D11,Supuestos!$C$85:$E$85) -> 175161.41
A13: VAE = VPN (A/P, 16 %, 5) (S/ por año) | B13: Pesimista | C13: Base | D13: Optimista | E13: VPN esperado
A14: Fase 1 (maquinaria, empaque, online, B2B) | B14: =Flujo_Pesimista!C80 -> -42594.697 | C14: =Flujo_Base!C80 -> 35830.575 | D14: =Flujo_Optimista!C80 -> 131423.56 | E14: =SUMPRODUCT(B14:D14,Supuestos!$C$85:$E$85) -> 40122.504
A15: Tiendas (Fase 2) | B15: =Flujo_Pesimista!C83 -> -149449.58 | C15: =Flujo_Base!C83 -> -59456.583 | D15: =Flujo_Optimista!C83 -> 26935.47 | E15: =SUMPRODUCT(B15:D15,Supuestos!$C$85:$E$85) -> -60356.818
A16: Proyecto completo | B16: =Flujo_Pesimista!C84 -> -192044.27 | C16: =Flujo_Base!C84 -> -23626.008 | D16: =Flujo_Optimista!C84 -> 158359.03 | E16: =SUMPRODUCT(B16:D16,Supuestos!$C$85:$E$85) -> -20234.314
A18: TIR por interpolación | B18: Pesimista | C18: Base | D18: Optimista
A19: Fase 1 (maquinaria, empaque, online, B2B) | B19: =Flujo_Pesimista!F91 -> -0.010922884 | C19: =Flujo_Base!F91 -> 0.27601443 | D19: =Flujo_Optimista!F91 -> 0.50820318
A20: Tiendas (Fase 2) | B20: =Flujo_Pesimista!F94 -> No existe | C20: =Flujo_Base!F94 -> -0.083591579 | D20: =Flujo_Optimista!F94 -> 0.25457728
A21: Proyecto completo | B21: =Flujo_Pesimista!F95 -> -0.29733354 | C21: =Flujo_Base!F95 -> 0.11957886 | D21: =Flujo_Optimista!F95 -> 0.39632394
A23: TER (TIR modificada) | B23: Pesimista | C23: Base | D23: Optimista
A24: Fase 1 (maquinaria, empaque, online, B2B) | B24: =Flujo_Pesimista!D103 -> 0.004616813 | C24: =Flujo_Base!D103 -> 0.24969849 | D24: =Flujo_Optimista!D103 -> 0.41017603
A25: Tiendas (Fase 2) | B25: =Flujo_Pesimista!D106 -> No existe | C25: =Flujo_Base!D106 -> -0.038938634 | D25: =Flujo_Optimista!D106 -> 0.2272416
A26: Proyecto completo | B26: =Flujo_Pesimista!D107 -> -0.24772231 | C26: =Flujo_Base!D107 -> 0.12454126 | D26: =Flujo_Optimista!D107 -> 0.33877494
A28: Relación B/C | B28: Pesimista | C28: Base | D28: Optimista
A29: Fase 1 (maquinaria, empaque, online, B2B) | B29: =Flujo_Pesimista!F80 -> 0.48794367 | C29: =Flujo_Base!F80 -> 1.4512301 | D29: =Flujo_Optimista!F80 -> 2.6550744
A30: Tiendas (Fase 2) | B30: =Flujo_Pesimista!F83 -> 0 | C30: =Flujo_Base!F83 -> 0.39535198 | D30: =Flujo_Optimista!F83 -> 1.3329361
A31: Proyecto completo | B31: =Flujo_Pesimista!F84 -> 0.11665905 | C31: =Flujo_Base!F84 -> 0.85996894 | D31: =Flujo_Optimista!F84 -> 2.0495536
A33: Tasas | B33: Valor
A34: Costo de la deuda después de impuestos Kd(1 − T) | B34: =Tasas!$C$6 -> 0.102225
A35: Costo del patrimonio (CAPM) | B35: =Tasas!$C$7 -> 0.10855
A36: CPPC nominal | B36: =Tasas!$C$8 -> 0.10380625
A37: CPPC real | B37: =Tasas!$C$9 -> 0.08216299
A38: TMAR real | B38: =Tasas!$C$10 -> 0.16
A39: TMAR inflada | B39: =Tasas!$C$12 -> 0.1832
A40: TMAR antes de impuestos | B40: =Tasas!$C$13 -> 0.22695035
A42: Préstamo: A = P (A/P, i_m, 36) | B42: S/ 480 mil | C42: S/ 260 mil
A43: Tasa efectiva mensual | B43: =Tasas!$C$5 -> 0.011347621 | C43: =Tasas!$C$5 -> 0.011347621
A44: Cuota mensual | B44: =Prestamo!F5 -> 16316.148 | C44: =Prestamo!L5 -> 8837.9137
A45: Cuota anual | B45: =Prestamo!F44 -> 195793.78 | C45: =Prestamo!L44 -> 106054.96
A46: Intereses totales | B46: =Prestamo!D49 -> 107381.34 | C46: =Prestamo!J49 -> 58164.892
A48: Punto de equilibrio Q = CF/(p − cv) | B48: Lima | C48: Arequipa
...

Sheet Paso_a_paso
A1: Ruta de la solución paso a paso (escenario base)
A2: Cada fila es un cálculo del documento. El resultado está vinculado a la hoja donde se calcula, así que cambia si cambias un supuesto.
A4: Paso | B4: Qué se calcula | C4: Fórmula del curso | D4: Resultado | E4: Hoja con el detalle
A5: 1 | B5: Costo unitario de producción (U) | C5: Suma de la tabla de costos | D5: =Costos_Margenes!B11 -> 49.5 | E5: Costos_Margenes
A6: 2 | B6: Costo anual de producción (método unitario) | C6: Ct = U × N | D6: =Costos_Margenes!D32 -> 519019.48 | E6: Costos_Margenes
A7: 3 | B7: Contribución por kg en tienda | C7: p − cv | D7: =Costos_Margenes!I15 -> 130.5 | E7: Costos_Margenes
A8: 3 | B8: Contribución por kg online | C8: p − (costo + flete + pasarela + marketing) | D8: =Costos_Margenes!I16 -> 79.02 | E8: Costos_Margenes
A9: 3 | B9: Contribución por kg B2B | C9: p (1 − comisión) − costo | D9: =Costos_Margenes!I17 -> 32.5 | E9: Costos_Margenes
A10: 4 | B10: Volumen vendido 2025 (kg) | C10: Ventas del canal ÷ precio por kg | D10: =Costos_Margenes!D24 -> 10485.242 | E10: Costos_Margenes
A11: 4 | B11: Uso promedio de la capacidad actual | C11: kg vendidos ÷ (80 kg × 300 días) | D11: =Costos_Margenes!B27 -> 0.43688509 | E11: Costos_Margenes
A12: 5 | B12: Tasa efectiva mensual del préstamo | C12: i_m = (1 + i_a)^(1/12) − 1 | D12: =Tasas!$C$5 -> 0.011347621 | E12: Tasas
A13: 5 | B13: Costo de la deuda después de impuestos | C13: K'd = Kd (1 − T) | D13: =Tasas!$C$6 -> 0.102225 | E13: Tasas
A14: 5 | B14: Costo del patrimonio (CAPM) | C14: Re = Rf + β (Rm − Rf) | D14: =Tasas!$C$7 -> 0.10855 | E14: Tasas
A15: 5 | B15: CPPC nominal | C15: CPPC = Wd·Kd(1 − T) + We·Ke | D15: =Tasas!$C$8 -> 0.10380625 | E15: Tasas
A16: 5 | B16: CPPC real | C16: i = (if − f) / (1 + f) | D16: =Tasas!$C$9 -> 0.08216299 | E16: Tasas
A17: 5 | B17: TMAR inflada | C17: if = i + f + i·f | D17: =Tasas!$C$12 -> 0.1832 | E17: Tasas
A18: 5 | B18: TMAR antes de impuestos | C18: TMAR / (1 − T) | D18: =Tasas!$C$13 -> 0.22695035 | E18: Tasas
A19: 6 | B19: Cuota mensual del préstamo de S/ 480 mil | C19: A = P (A/P, i_m, 36) | D19: =Prestamo!F5 -> 16316.148 | E19: Prestamo
A20: 8 | B20: Ventas online incrementales año 1 | C20: V_2025 × [(1 + g)^t − 1] | D20: =Flujo_Base!C8 -> 89910 | E20: Flujo_Base
A21: 8 | B21: Flujo económico Fase 1, año 5 | C21: UODI + depreciación − inversión − ΔCT + rescate | D21: =Flujo_Base!G26 -> 378102.21 | E21: Flujo_Base
A22: 10 | B22: VPN Fase 1 | C22: VPN = Σ F_t (P/F, i, t) | D22: =Flujo_Base!B80 -> 117319.82 | E22: Flujo_Base
A23: 10 | B23: VPN tiendas | C23: VPN = Σ F_t (P/F, i, t) | D23: =Flujo_Base!B83 -> -194678.31 | E23: Flujo_Base
A24: 10 | B24: VPN proyecto completo | C24: VPN = Σ F_t (P/F, i, t) | D24: =Flujo_Base!B84 -> -77358.488 | E24: Flujo_Base
A25: 11 | B25: VAE Fase 1 | C25: VAE = VPN (A/P, i, n) | D25: =Flujo_Base!C80 -> 35830.575 | E25: Flujo_Base
A26: 11 | B26: TIR Fase 1 (interpolación) | C26: TIR = i1 + VPN1/(VPN1 − VPN2)·(i2 − i1) | D26: =Flujo_Base!F91 -> 0.27601443 | E26: Flujo_Base
A27: 11 | B27: TIR proyecto completo (interpolación) | C27: TIR = i1 + VPN1/(VPN1 − VPN2)·(i2 − i1) | D27: =Flujo_Base!F95 -> 0.11957886 | E27: Flujo_Base
A28: 11 | B28: TER Fase 1 | C28: TER = (VF_pos / VP_neg)^(1/n) − 1 | D28: =Flujo_Base!D103 -> 0.24969849 | E28: Flujo_Base
A29: 11 | B29: B/C Fase 1 | C29: B/C = VP beneficios / VP costos | D29: =Flujo_Base!F80 -> 1.4512301 | E29: Flujo_Base
A30: 11 | B30: B/C proyecto completo | C30: B/C = VP beneficios / VP costos | D30: =Flujo_Base!F84 -> 0.85996894 | E30: Flujo_Base
A31: 11 | B31: Recuperación descontada Fase 1 (años) | C31: Año en que el VP acumulado pasa a positivo | D31: =Flujo_Base!G80 -> 4.3482934 | E31: Flujo_Base
A32: 12 | B32: VPN esperado Fase 1 | C32: Σ probabilidad × VPN del escenario | D32: =Resumen!E5 -> 131372.86 | E32: Resumen
A33: 12 | B33: VPN esperado proyecto completo | C33: Σ probabilidad × VPN del escenario | D33: =Resumen!E9 -> -66253.085 | E33: Resumen
A34: 13 | B34: ΔB/C proyecto completo vs. Fase 1 | C34: ΔB/C = ΔB / ΔC | D34: =Incremental!C14 -> 0.33429217 | E34: Incremental
A35: 14 | B35: VPN financiero proyecto completo | C35: Flujo económico − servicio de deuda en soles constantes | D35: =Flujo_Base!B85 -> 3481.9023 | E35: Flujo_Base
A36: 14 | B36: VPN financiero solo Fase 1 | C36: Flujo económico − servicio de deuda en soles constantes | D36: =Flujo_Base!B86 -> 161108.37 | E36: Flujo_Base
A37: 14 | B37: VPN Fase 1 en soles corrientes a TMAR inflada | C37: Σ F_t (1 + f)^t / (1 + if)^t | D37: =Inflacion!F15 -> 117319.82 | E37: Inflacion
A38: 15 | B38: Ventas de equilibrio Lima con recuperación de inversión | C38: Q = (CF + A) / (p − cv) × p | D38: =Equilibrio!B14 -> 408906.58 | E38: Equilibrio
A39: 15 | B39: Ventas de equilibrio Arequipa con recuperación de inversión | C39: Q = (CF + A) / (p − cv) × p | D39: =Equilibrio!C14 -> 254891.53 | E39: Equilibrio
A40: 15 | B40: Kg online de equilibrio de la Fase 1 | C40: Q = [CF + I(A/P) − S(A/F)] / (p − cv) | D40: =Equilibrio!B26 -> 1695.233 | E40: Equilibrio
A41: 16 | B41: VP de las ventas online incrementales (gradiente) | C41: A1 (P/A, g, i, n) − V (P/A, i, n) | D41: =Factores!C26 -> 994179.7 | E41: Factores

Sheet Supuestos
A1: Aromas del Valle — Supuestos del modelo
A2: Texto azul = dato de entrada (editable). Fondo amarillo = supuesto propio (no viene del caso). Negro = fórmula. Montos en soles constantes de 2025 (S/).
A4: Concepto | C4: Valor | D4: Unidad | E4: Fuente / comentario | F4: Año 1 | G4: Año 2 | H4: Año 3 | I4: Año 4 | J4: Año 5
A5: 1. Tasas y parámetros generales
A6: TMAR real (rendimiento mínimo exigido, en soles constantes) | C6: 0.16 | E6: Supuesto: CPPC + prima de riesgo de una PYME con tiendas nuevas (ver hoja Tasas)
A7: Impuesto a la Renta (T) | C7: 0.295 | E7: Perú, régimen general. Las pérdidas del proyecto generan escudo porque la empresa ya tiene utilidades
A8: Inflación anual esperada (f) | C8: 0.02 | E8: Supuesto: centro del rango meta del BCRP (1–3 %)
A9: Capital de trabajo requerido (% de ventas incrementales) | C9: 0.1 | E9: Supuesto: nunca baja del capital de trabajo inicial; se recupera en el año 5
A10: Horizonte de evaluación | C10: 5 | D10: años | E10: Años 2026–2030
A12: 2. Costo de capital (CAPM y CPPC)
A13: Tasa libre de riesgo Rf | C13: 0.065 | E13: BCRP: rendimiento del bono soberano a 10 años en soles, setiembre 2026 (6.5 %)
A14: Beta (β) del sector | C14: 0.67 | E14: Damodaran, Food Processing (global), datos de enero 2026
A15: Prima de mercado (Rm − Rf) | C15: 0.065 | E15: Supuesto: prima de mercado madura ≈ 4.5 % + riesgo país ≈ 2 %
A16: Peso de la deuda (Wd) | C16: 0.75 | E16: Supuesto: el préstamo cubre la inversión fija; los dueños aportan el capital de trabajo
A17: Peso del patrimonio (We) | C17: =1-C16 -> 0.25 | E17: We = 1 − Wd
A19: 3. Costo de producción por kg tostado (S/)
A20: Café verde (incluye flete interno) | C20: 28.5 | D20: S/ por kg | E20: Caso: tabla de costos por kg tostado (2025)
A21: Merma de tostado (15–16 %) | C21: 5.2 | D21: S/ por kg | E21: Caso: tabla de costos por kg tostado (2025)
A22: Mano de obra directa de tostado | C22: 3.8 | D22: S/ por kg | E22: Caso: tabla de costos por kg tostado (2025)
A23: Energía y gas | C23: 2.1 | D23: S/ por kg | E23: Caso: tabla de costos por kg tostado (2025)
A24: Empaque (bolsa + válvula + etiqueta) | C24: 4.9 | D24: S/ por kg | E24: Caso: tabla de costos por kg tostado (2025)
A25: Control de calidad y laboratorio | C25: 1.4 | D25: S/ por kg | E25: Caso: tabla de costos por kg tostado (2025)
A26: Costos indirectos de producción | C26: 3.6 | D26: S/ por kg | E26: Caso: tabla de costos por kg tostado (2025)
A27: Costo unitario total (U) | C27: =SUM(C20:C26) -> 49.5 | E27: Suma de la tabla = 49.50
A29: 4. Precios y costos por canal
A30: Precio tienda por kg (250 g a S/ 42–48) | C30: 180 | D30: S/ por kg | E30: Caso: S/ 168–192 por kg (punto medio)
A31: Precio online por kg (500 g a S/ 78–88) | C31: 166 | D31: S/ por kg | E31: Caso: punto medio S/ 83 por 500 g
A32: Flete online por kg | C32: 28 | D32: S/ por kg | E32: Caso: S/ 14 por 500 g
A33: Comisión pasarela de pago / WhatsApp Business | C33: 0.03 | E33: Caso: 2.5–3.5 % (punto medio)
A34: Marketing online por kg | C34: 4.5 | D34: S/ por kg | E34: Caso
A35: Precio mayorista a cafeterías por kg | C35: 102.5 | D35: S/ por kg | E35: Caso: punto medio de S/ 95–110
A36: Comisión a cafeterías y hoteles | C36: 0.2 | E36: Caso: punto medio de 15–25 % del precio de lista
A38: 5. Situación actual (2025)
A39: Facturación 2025 | C39: 1850000 | E39: Caso: ≈ S/ 1.85 millones
A40: Participación tienda física | C40: 0.58 | E40: Caso
A41: Participación online | C41: 0.27 | E41: Caso
A42: Participación cafeterías y hoteles (B2B) | C42: 0.15 | E42: Caso
A43: Ventas tienda Cusco | C43: =Supuestos!$C$39*Supuestos!$C$40 -> 1073000 | E43: Facturación × participación
A44: Ventas online | C44: =Supuestos!$C$39*Supuestos!$C$41 -> 499500 | E44: Facturación × participación
A45: Ventas B2B | C45: =Supuestos!$C$39*Supuestos!$C$42 -> 277500 | E45: Facturación × participación
...

Sheet Tasas
A1: Tasas: préstamo, costo de capital, TMAR e inflación
A2: Fórmulas del curso. Todas las celdas negras se recalculan desde la hoja Supuestos.
A4: Concepto | B4: Fórmula | C4: Valor | D4: Lectura
A5: Tasa efectiva mensual del préstamo | B5: i_m = (1 + i_a)^(1/12) − 1 | C5: =(1+Supuestos!$C$76)^(1/12)-1 -> 0.011347621 | D5: Convierte la TEA de 14.5 % en tasa mensual
A6: Costo de la deuda después de impuestos | B6: K'd = Kd (1 − T) | C6: =Supuestos!$C$76*(1-Supuestos!$C$7) -> 0.102225 | D6: El interés es deducible: la deuda cuesta menos de lo que dice su tasa
A7: Costo del patrimonio (CAPM) | B7: Re = Rf + β (Rm − Rf) | C7: =Supuestos!$C$13+Supuestos!$C$14*Supuestos!$C$15 -> 0.10855 | D7: Rendimiento mínimo de una empresa cotizada del sector
A8: CPPC (WACC), nominal | B8: CPPC = Wd·Kd(1 − T) + We·Ke | C8: =Supuestos!$C$16*Tasas!$C$6+Supuestos!$C$17*Tasas!$C$7 -> 0.10380625 | D8: Costo promedio de las fuentes de financiamiento
A9: CPPC en términos reales | B9: i = (if − f) / (1 + f) | C9: =(Tasas!$C$8-Supuestos!$C$8)/(1+Supuestos!$C$8) -> 0.08216299 | D9: Se despeja la tasa real de if = i + f + i·f
A10: TMAR real usada en el modelo | B10: Supuesto | C10: =Supuestos!$C$6 -> 0.16 | D10: Debe ser ≥ CPPC real; la diferencia es la prima por riesgo del proyecto
A11: Prima de riesgo implícita | B11: TMAR − CPPC real | C11: =Tasas!$C$10-Tasas!$C$9 -> 0.07783701 | D11: Riesgo de PYME, tiendas nuevas y menor liquidez
A12: TMAR inflada (a valor de mercado) | B12: if = i + f + i·f | C12: =Supuestos!$C$6+Supuestos!$C$8+Supuestos!$C$6*Supuestos!$C$8 -> 0.1832 | D12: Para descontar flujos en soles corrientes
A13: TMAR antes de impuestos | B13: TMAR antes = TMAR después / (1 − T) | C13: =Supuestos!$C$6/(1-Supuestos!$C$7) -> 0.22695035 | D13: Para descontar flujos antes de impuestos
A14: Costo real del préstamo (tasa i_b para la TER) | B14: i = (Kd − f) / (1 + f) | C14: =(Supuestos!$C$76-Supuestos!$C$8)/(1+Supuestos!$C$8) -> 0.12254902 | D14: Tasa a la que se financian los flujos negativos
A16: Verificación TMAR ≥ CPPC real | C16: =IF(Tasas!$C$10>=Tasas!$C$9,"Cumple","No cumple") -> Cumple
A18: Nota: el CAPM usa la beta de empresas cotizadas; una PYME familiar con tiendas nuevas tiene más riesgo, por eso la TMAR (16 %) supera al CPPC.
A19: No se usa el costo de capital por dividendos (Re = D1/P + g) porque la empresa no cotiza ni reparte dividendos regulares.

Sheet Factores
A1: Factores de interés compuesto a la TMAR real
A2: Fórmulas del curso: (P/F), (F/P), (P/A), (A/P), (A/F), (F/A) y gradiente geométrico (P/A, g, i, n).
A4: t (años) | B4: (P/F, i, t) = 1/(1+i)^t | C4: (F/P, i, t) = (1+i)^t
A5: 0 | B5: =1/(1+Supuestos!$C$6)^A5 -> 1 | C5: =(1+Supuestos!$C$6)^A5 -> 1
A6: 1 | B6: =1/(1+Supuestos!$C$6)^A6 -> 0.86206897 | C6: =(1+Supuestos!$C$6)^A6 -> 1.16
A7: 2 | B7: =1/(1+Supuestos!$C$6)^A7 -> 0.7431629 | C7: =(1+Supuestos!$C$6)^A7 -> 1.3456
A8: 3 | B8: =1/(1+Supuestos!$C$6)^A8 -> 0.64065767 | C8: =(1+Supuestos!$C$6)^A8 -> 1.560896
A9: 4 | B9: =1/(1+Supuestos!$C$6)^A9 -> 0.5522911 | C9: =(1+Supuestos!$C$6)^A9 -> 1.8106394
A10: 5 | B10: =1/(1+Supuestos!$C$6)^A10 -> 0.47611302 | C10: =(1+Supuestos!$C$6)^A10 -> 2.1003417
A12: Factor de serie uniforme (n = 5) | B12: Fórmula | C12: Valor
A13: (P/A, i, n) | B13: [(1+i)^n − 1] / [i(1+i)^n] | C13: =((1+Supuestos!$C$6)^Supuestos!$C$10-1)/(Supuestos!$C$6*(1+Supuestos!$C$6)^Supuestos!$C$10) -> 3.2742937
A14: (A/P, i, n) | B14: i(1+i)^n / [(1+i)^n − 1] | C14: =(Supuestos!$C$6*(1+Supuestos!$C$6)^Supuestos!$C$10)/((1+Supuestos!$C$6)^Supuestos!$C$10-1) -> 0.30540938
A15: (A/F, i, n) | B15: i / [(1+i)^n − 1] | C15: =Supuestos!$C$6/((1+Supuestos!$C$6)^Supuestos!$C$10-1) -> 0.14540938
A16: (F/A, i, n) | B16: [(1+i)^n − 1] / i | C16: =((1+Supuestos!$C$6)^Supuestos!$C$10-1)/Supuestos!$C$6 -> 6.8771354
A17: (A/P, i_m, 36) del préstamo | B17: i_m(1+i_m)^n / [(1+i_m)^n − 1] | C17: =(Tasas!$C$5*(1+Tasas!$C$5)^Supuestos!$C$77)/((1+Tasas!$C$5)^Supuestos!$C$77-1) -> 0.033991976
A19: i = TMAR real; n = horizonte (5 años). Ejemplo: 260,000 (A/P, 16 %, 5) = costo anual equivalente de la inversión de la Fase 1.
A21: Gradiente geométrico: ventas online (escenario base) | B21: Fórmula | C21: Valor
A22: Ventas online del año 1 (A1) | B22: A1 = ventas 2025 × (1 + g) | C22: =Supuestos!$C$44*(1+Supuestos!$D$81) -> 589410
A23: (P/A, g, i, n) | B23: [1 − ((1+g)/(1+i))^n] / (i − g) | C23: =IF(Supuestos!$D$81=Supuestos!$C$6,Supuestos!$C$10/(1+Supuestos!$C$6),(1-((1+Supuestos!$D$81)/(1+Supuestos!$C$6))^Supuestos!$C$10)/(Supuestos!$C$6-Supuestos!$D$81)) -> 4.4615622
A24: VP de las ventas online totales | B24: A1 × (P/A, g, i, n) | C24: =Factores!$C$22*Factores!$C$23 -> 2629689.4
A25: VP de las ventas online sin proyecto | B25: Ventas 2025 × (P/A, i, n) | C25: =Supuestos!$C$44*Factores!$C$13 -> 1635509.7
A26: VP de las ventas online incrementales | B26: VP total − VP sin proyecto | C26: =Factores!$C$24-Factores!$C$25 -> 994179.7
A27: Mismo valor calculado año por año en el flujo | B27: Σ ventas_t × (P/F, i, t) | C27: =SUMPRODUCT(Flujo_Base!C8:G8,Flujo_Base!C6:G6) -> 994179.7
A28: Diferencia (comprobación) | B28: Debe ser 0 | C28: =Factores!$C$26-Factores!$C$27 -> -9.3132257e-09

Sheet Costos_Margenes
A1: Costo por kg, margen por canal, volumen y método unitario
A3: Rubro | B3: S/ por kg | C3: % calculado | D3: % que dice el caso
A4: Café verde (incluye flete interno) | B4: =Supuestos!$C$20 -> 28.5 | C4: =B4/$B$11 -> 0.57575758 | D4: 0.52
A5: Merma de tostado (15–16 %) | B5: =Supuestos!$C$21 -> 5.2 | C5: =B5/$B$11 -> 0.10505051 | D5: 0.095
A6: Mano de obra directa de tostado | B6: =Supuestos!$C$22 -> 3.8 | C6: =B6/$B$11 -> 0.076767677 | D6: 0.07
A7: Energía y gas | B7: =Supuestos!$C$23 -> 2.1 | C7: =B7/$B$11 -> 0.042424242 | D7: 0.038
A8: Empaque (bolsa + válvula + etiqueta) | B8: =Supuestos!$C$24 -> 4.9 | C8: =B8/$B$11 -> 0.098989899 | D8: 0.09
A9: Control de calidad y laboratorio | B9: =Supuestos!$C$25 -> 1.4 | C9: =B9/$B$11 -> 0.028282828 | D9: 0.025
A10: Costos indirectos de producción | B10: =Supuestos!$C$26 -> 3.6 | C10: =B10/$B$11 -> 0.072727273 | D10: 0.066
A11: Costo total | B11: =SUM(B4:B10) -> 49.5 | C11: =SUM(C4:C10) -> 1 | D11: =SUM(D4:D10) -> 0.904
A12: Café verde + merma (% del costo) | C12: =C4+C5 -> 0.68080808 | D12: =D4+D5 -> 0.615
A13: Los porcentajes del caso suman 90.4 %, no 100 %: no cuadran con los soles. El modelo usa los soles por kg, que sí suman S/ 49.50.
A14: Canal | B14: Precio p (S/ por kg) | C14: Costo prod. | D14: Flete | E14: Pasarela | F14: Marketing | G14: Comisión B2B | H14: Costo variable cv | I14: Contribución p − cv | J14: Margen %
A15: Tienda Cusco | B15: =Supuestos!$C$30 -> 180 | C15: =Supuestos!$C$27 -> 49.5 | D15: =0 -> 0 | E15: =0 -> 0 | F15: =0 -> 0 | G15: =0 -> 0 | H15: =SUM(C15:G15) -> 49.5 | I15: =B15-H15 -> 130.5 | J15: =I15/B15 -> 0.725
A16: Online | B16: =Supuestos!$C$31 -> 166 | C16: =Supuestos!$C$27 -> 49.5 | D16: =Supuestos!$C$32 -> 28 | E16: =Supuestos!$C$33*B16 -> 4.98 | F16: =Supuestos!$C$34 -> 4.5 | G16: =0 -> 0 | H16: =SUM(C16:G16) -> 86.98 | I16: =B16-H16 -> 79.02 | J16: =I16/B16 -> 0.4760241
A17: B2B | B17: =Supuestos!$C$35 -> 102.5 | C17: =Supuestos!$C$27 -> 49.5 | D17: =0 -> 0 | E17: =0 -> 0 | F17: =0 -> 0 | G17: =Supuestos!$C$36*B17 -> 20.5 | H17: =SUM(C17:G17) -> 70 | I17: =B17-H17 -> 32.5 | J17: =I17/B17 -> 0.31707317
A18: Tienda: margen antes de alquiler y personal. El 42 % del caso incluye esos costos fijos no detallados.
A20: Canal | B20: Ventas 2025 (S/) | C20: Precio por kg | D20: Kg por año
A21: Tienda Cusco (solo café) | B21: =Supuestos!$C$43*Supuestos!$C$46 -> 858400 | C21: =B15 -> 180 | D21: =B21/C21 -> 4768.8889
A22: Online | B22: =Supuestos!$C$44 -> 499500 | C22: =B16 -> 166 | D22: =B22/C22 -> 3009.0361
A23: B2B | B23: =Supuestos!$C$45 -> 277500 | C23: =B17 -> 102.5 | D23: =B23/C23 -> 2707.3171
A24: Total | B24: =SUM(B21:B23) -> 1635400 | D24: =SUM(D21:D23) -> 10485.242
A26: Capacidad actual (kg/año) | B26: =Supuestos!$C$47*Supuestos!$C$49 -> 24000
A27: Uso promedio de la capacidad actual | B27: =D24/B26 -> 0.43688509
A28: Capacidad con máquina nueva (kg/año) | B28: =Supuestos!$C$48*Supuestos!$C$49 -> 75000
A29: Capacidad nueva ÷ volumen actual | B29: =B28/D24 -> 7.1529107
A31: Método unitario: Ct = U × N | B31: U (S/ por kg) | C31: N (kg por año) | D31: Ct (S/ por año) | E31: Ct − 20 % | F31: Ct + 20 %
A32: Costo de producción actual (2025) | B32: =Supuestos!$C$27 -> 49.5 | C32: =D24 -> 10485.242 | D32: =B32*C32 -> 519019.48 | E32: =D32*(1-0.2) -> 415215.59 | F32: =D32*(1+0.2) -> 622823.38
A33: Costo de producción año 5, escenario base | B33: =Supuestos!$C$27 -> 49.5 | C33: =Flujo_Base!G9 -> 15984.542 | D33: =B33*C33 -> 791234.83 | E33: =D33*(1-0.2) -> 632987.86 | F33: =D33*(1+0.2) -> 949481.79
A34: Precisión de ±20 %, aceptable en una estimación preliminar (como en el ejemplo de las tuberías).

Sheet Prestamo
A1: Préstamo: cuota constante A = P (A/P, i_m, n)
A2: i_m = (1 + 0.145)^(1/12) − 1 ; n = 36 meses. El interés de cada mes = saldo × i_m.
C3: Préstamo S/ 480 mil (proyecto completo) | I3: Préstamo S/ 260 mil (solo Fase 1)
A4: Mes | B4: Año | C4: Saldo inicial | D4: Interés | E4: Amortización | F4: Cuota | G4: Saldo final | I4: Saldo inicial | J4: Interés | K4: Amortización | L4: Cuota | M4: Saldo final
A5: 1 | B5: =ROUNDUP(A5/12,0) -> 1 | C5: =Supuestos!$C$74 -> 480000 | D5: =C5*Tasas!$C$5 -> 5446.8581 | E5: =F5-D5 -> 10869.29 | F5: =Supuestos!$C$74*Factores!$C$17 -> 16316.148 | G5: =C5-E5 -> 469130.71 | I5: =Supuestos!$C$75 -> 260000 | J5: =I5*Tasas!$C$5 -> 2950.3815 | K5: =L5-J5 -> 5887.5322 | L5: =Supuestos!$C$75*Factores!$C$17 -> 8837.9137 | M5: =I5-K5 -> 254112.47
A6: 2 | B6: =ROUNDUP(A6/12,0) -> 1 | C6: =G5 -> 469130.71 | D6: =C6*Tasas!$C$5 -> 5323.5175 | E6: =F6-D6 -> 10992.631 | F6: =Supuestos!$C$74*Factores!$C$17 -> 16316.148 | G6: =C6-E6 -> 458138.08 | I6: =M5 -> 254112.47 | J6: =I6*Tasas!$C$5 -> 2883.572 | K6: =L6-J6 -> 5954.3417 | L6: =Supuestos!$C$75*Factores!$C$17 -> 8837.9137 | M6: =I6-K6 -> 248158.13
A7: 3 | B7: =ROUNDUP(A7/12,0) -> 1 | C7: =G6 -> 458138.08 | D7: =C7*Tasas!$C$5 -> 5198.7773 | E7: =F7-D7 -> 11117.371 | F7: =Supuestos!$C$74*Factores!$C$17 -> 16316.148 | G7: =C7-E7 -> 447020.71 | I7: =M6 -> 248158.13 | J7: =I7*Tasas!$C$5 -> 2816.0044 | K7: =L7-J7 -> 6021.9093 | L7: =Supuestos!$C$75*Factores!$C$17 -> 8837.9137 | M7: =I7-K7 -> 242136.22
A8: 4 | B8: =ROUNDUP(A8/12,0) -> 1 | C8: =G7 -> 447020.71 | D8: =C8*Tasas!$C$5 -> 5072.6216 | E8: =F8-D8 -> 11243.527 | F8: =Supuestos!$C$74*Factores!$C$17 -> 16316.148 | G8: =C8-E8 -> 435777.18 | I8: =M7 -> 242136.22 | J8: =I8*Tasas!$C$5 -> 2747.67 | K8: =L8-J8 -> 6090.2436 | L8: =Supuestos!$C$75*Factores!$C$17 -> 8837.9137 | M8: =I8-K8 -> 236045.97
A9: 5 | B9: =ROUNDUP(A9/12,0) -> 1 | C9: =G8 -> 435777.18 | D9: =C9*Tasas!$C$5 -> 4945.0343 | E9: =F9-D9 -> 11371.114 | F9: =Supuestos!$C$74*Factores!$C$17 -> 16316.148 | G9: =C9-E9 -> 424406.07 | I9: =M8 -> 236045.97 | J9: =I9*Tasas!$C$5 -> 2678.5603 | K9: =L9-J9 -> 6159.3534 | L9: =Supuestos!$C$75*Factores!$C$17 -> 8837.9137 | M9: =I9-K9 -> 229886.62
A10: 6 | B10: =ROUNDUP(A10/12,0) -> 1 | C10: =G9 -> 424406.07 | D10: =C10*Tasas!$C$5 -> 4815.9992 | E10: =F10-D10 -> 11500.149 | F10: =Supuestos!$C$74*Factores!$C$17 -> 16316.148 | G10: =C10-E10 -> 412905.92 | I10: =M9 -> 229886.62 | J10: =I10*Tasas!$C$5 -> 2608.6662 | K10: =L10-J10 -> 6229.2474 | L10: =Supuestos!$C$75*Factores!$C$17 -> 8837.9137 | M10: =I10-K10 -> 223657.37
A11: 7 | B11: =ROUNDUP(A11/12,0) -> 1 | C11: =G10 -> 412905.92 | D11: =C11*Tasas!$C$5 -> 4685.4999 | E11: =F11-D11 -> 11630.648 | F11: =Supuestos!$C$74*Factores!$C$17 -> 16316.148 | G11: =C11-E11 -> 401275.27 | I11: =M10 -> 223657.37 | J11: =I11*Tasas!$C$5 -> 2537.9791 | K11: =L11-J11 -> 6299.9345 | L11: =Supuestos!$C$75*Factores!$C$17 -> 8837.9137 | M11: =I11-K11 -> 217357.44
A12: 8 | B12: =ROUNDUP(A12/12,0) -> 1 | C12: =G11 -> 401275.27 | D12: =C12*Tasas!$C$5 -> 4553.5197 | E12: =F12-D12 -> 11762.629 | F12: =Supuestos!$C$74*Factores!$C$17 -> 16316.148 | G12: =C12-E12 -> 389512.64 | I12: =M11 -> 217357.44 | J12: =I12*Tasas!$C$5 -> 2466.4898 | K12: =L12-J12 -> 6371.4238 | L12: =Supuestos!$C$75*Factores!$C$17 -> 8837.9137 | M12: =I12-K12 -> 210986.01
A13: 9 | B13: =ROUNDUP(A13/12,0) -> 1 | C13: =G12 -> 389512.64 | D13: =C13*Tasas!$C$5 -> 4420.0418 | E13: =F13-D13 -> 11896.106 | F13: =Supuestos!$C$74*Factores!$C$17 -> 16316.148 | G13: =C13-E13 -> 377616.53 | I13: =M12 -> 210986.01 | J13: =I13*Tasas!$C$5 -> 2394.1893 | K13: =L13-J13 -> 6443.7243 | L13: =Supuestos!$C$75*Factores!$C$17 -> 8837.9137 | M13: =I13-K13 -> 204542.29
A14: 10 | B14: =ROUNDUP(A14/12,0) -> 1 | C14: =G13 -> 377616.53 | D14: =C14*Tasas!$C$5 -> 4285.0493 | E14: =F14-D14 -> 12031.099 | F14: =Supuestos!$C$74*Factores!$C$17 -> 16316.148 | G14: =C14-E14 -> 365585.44 | I14: =M13 -> 204542.29 | J14: =I14*Tasas!$C$5 -> 2321.0684 | K14: =L14-J14 -> 6516.8453 | L14: =Supuestos!$C$75*Factores!$C$17 -> 8837.9137 | M14: =I14-K14 -> 198025.44
A15: 11 | B15: =ROUNDUP(A15/12,0) -> 1 | C15: =G14 -> 365585.44 | D15: =C15*Tasas!$C$5 -> 4148.525 | E15: =F15-D15 -> 12167.623 | F15: =Supuestos!$C$74*Factores!$C$17 -> 16316.148 | G15: =C15-E15 -> 353417.81 | I15: =M14 -> 198025.44 | J15: =I15*Tasas!$C$5 -> 2247.1177 | K15: =L15-J15 -> 6590.796 | L15: =Supuestos!$C$75*Factores!$C$17 -> 8837.9137 | M15: =I15-K15 -> 191434.65
A16: 12 | B16: =ROUNDUP(A16/12,0) -> 1 | C16: =G15 -> 353417.81 | D16: =C16*Tasas!$C$5 -> 4010.4514 | E16: =F16-D16 -> 12305.697 | F16: =Supuestos!$C$74*Factores!$C$17 -> 16316.148 | G16: =C16-E16 -> 341112.12 | I16: =M15 -> 191434.65 | J16: =I16*Tasas!$C$5 -> 2172.3278 | K16: =L16-J16 -> 6665.5858 | L16: =Supuestos!$C$75*Factores!$C$17 -> 8837.9137 | M16: =I16-K16 -> 184769.06
A17: 13 | B17: =ROUNDUP(A17/12,0) -> 2 | C17: =G16 -> 341112.12 | D17: =C17*Tasas!$C$5 -> 3870.811 | E17: =F17-D17 -> 12445.337 | F17: =Supuestos!$C$74*Factores!$C$17 -> 16316.148 | G17: =C17-E17 -> 328666.78 | I17: =M16 -> 184769.06 | J17: =I17*Tasas!$C$5 -> 2096.6893 | K17: =L17-J17 -> 6741.2243 | L17: =Supuestos!$C$75*Factores!$C$17 -> 8837.9137 | M17: =I17-K17 -> 178027.84
... A40: 36 | B40: =ROUNDUP(A40/12,0) -> 3 | C40: =G39 -> 16133.076 | D40: =C40*Tasas!$C$5 -> 183.07204 | E40: =F40-D40 -> 16133.076 | F40: =Supuestos!$C$74*Factores!$C$17 -> 16316.148 | G40: =C40-E40 -> 0 | I40: =M39 -> 8738.7496 | J40: =I40*Tasas!$C$5 -> 99.164019 | K40: =L40-J40 -> 8738.7496 | L40: =Supuestos!$C$75*Factores!$C$17 -> 8837.9137 | M40: =I40-K40 -> -1.036824e-10
A43: Resumen anual | B43: Año | D43: Interés | E43: Amortización | F43: Cuota | J43: Interés | K43: Amortización | L43: Cuota
A44: Año 1 | B44: 1 | D44: =SUMIF($B$5:$B$40,$B44,D$5:D$40) -> 56905.895 | E44: =SUMIF($B$5:$B$40,$B44,E$5:E$40) -> 138887.88 | F44: =SUMIF($B$5:$B$40,$B44,F$5:F$40) -> 195793.78 | J44: =SUMIF($B$5:$B$40,$B44,J$5:J$40) -> 30824.027 | K44: =SUMIF($B$5:$B$40,$B44,K$5:K$40) -> 75230.937 | L44: =SUMIF($B$5:$B$40,$B44,L$5:L$40) -> 106054.96
A45: Año 2 | B45: 2 | D45: =SUMIF($B$5:$B$40,$B45,D$5:D$40) -> 36767.152 | E45: =SUMIF($B$5:$B$40,$B45,E$5:E$40) -> 159026.63 | F45: =SUMIF($B$5:$B$40,$B45,F$5:F$40) -> 195793.78 | J45: =SUMIF($B$5:$B$40,$B45,J$5:J$40) -> 19915.541 | K45: =SUMIF($B$5:$B$40,$B45,K$5:K$40) -> 86139.423 | L45: =SUMIF($B$5:$B$40,$B45,L$5:L$40) -> 106054.96
A46: Año 3 | B46: 3 | D46: =SUMIF($B$5:$B$40,$B46,D$5:D$40) -> 13708.291 | E46: =SUMIF($B$5:$B$40,$B46,E$5:E$40) -> 182085.49 | F46: =SUMIF($B$5:$B$40,$B46,F$5:F$40) -> 195793.78 | J46: =SUMIF($B$5:$B$40,$B46,J$5:J$40) -> 7425.3243 | K46: =SUMIF($B$5:$B$40,$B46,K$5:K$40) -> 98629.64 | L46: =SUMIF($B$5:$B$40,$B46,L$5:L$40) -> 106054.96
A47: Año 4 | B47: 4 | D47: =SUMIF($B$5:$B$40,$B47,D$5:D$40) -> 0 | E47: =SUMIF($B$5:$B$40,$B47,E$5:E$40) -> 0 | F47: =SUMIF($B$5:$B$40,$B47,F$5:F$40) -> 0 | J47: =SUMIF($B$5:$B$40,$B47,J$5:J$40) -> 0 | K47: =SUMIF($B$5:$B$40,$B47,K$5:K$40) -> 0 | L47: =SUMIF($B$5:$B$40,$B47,L$5:L$40) -> 0
A48: Año 5 | B48: 5 | D48: =SUMIF($B$5:$B$40,$B48,D$5:D$40) -> 0 | E48: =SUMIF($B$5:$B$40,$B48,E$5:E$40) -> 0 | F48: =SUMIF($B$5:$B$40,$B48,F$5:F$40) -> 0 | J48: =SUMIF($B$5:$B$40,$B48,J$5:J$40) -> 0 | K48: =SUMIF($B$5:$B$40,$B48,K$5:K$40) -> 0 | L48: =SUMIF($B$5:$B$40,$B48,L$5:L$40) -> 0
A49: Total | D49: =SUM(D44:D48) -> 107381.34 | E49: =SUM(E44:E48) -> 480000 | F49: =SUM(F44:F48) -> 587381.34 | J49: =SUM(J44:J48) -> 58164.892 | K49: =SUM(K44:K48) -> 260000 | L49: =SUM(L44:L48) -> 318164.89

Sheet Flujo_Pesimista
A1: Flujo de caja incremental — escenario Pesimista
A2: Soles constantes de 2025, después de impuestos. VPN = Σ F_t × (P/F, TMAR, t).
I3: Auxiliar: VPN a distintas tasas (para interpolar la TIR) | AF3: Auxiliar: flujo descontado acumulado y año de recuperación
A4: Concepto | B4: Año 0 | C4: Año 1 | D4: Año 2 | E4: Año 3 | F4: Año 4 | G4: Año 5 | J4: -0.4 | K4: -0.35 | L4: -0.3 | M4: -0.25 | N4: -0.2 | O4: -0.15 | P4: -0.1 | Q4: -0.05 | R4: 0 | S4: 0.05 | T4: 0.1 | U4: 0.15 | V4: 0.2 | W4: 0.25 | X4: 0.3 | Y4: 0.35 | Z4: 0.4 | AA4: 0.45 | AB4: 0.5 | AC4: 0.55 | AD4: 0.6
A5: Periodo t | B5: 0 | C5: 1 | D5: 2 | E5: 3 | F5: 4 | G5: 5 | I5: Fase 1 | J5: =SUMPRODUCT($B$26:$G$26,(1+J$4)^(-$B$5:$G$5)) -> 2546750.2 | K5: =SUMPRODUCT($B$26:$G$26,(1+K$4)^(-$B$5:$G$5)) -> 1651425.6 | L5: =SUMPRODUCT($B$26:$G$26,(1+L$4)^(-$B$5:$G$5)) -> 1080618.3 | M5: =SUMPRODUCT($B$26:$G$26,(1+M$4)^(-$B$5:$G$5)) -> 704323.72 | N5: =SUMPRODUCT($B$26:$G$26,(1+N$4)^(-$B$5:$G$5)) -> 448973.64 | O5: =SUMPRODUCT($B$26:$G$26,(1+O$4)^(-$B$5:$G$5)) -> 271259.1 | P5: =SUMPRODUCT($B$26:$G$26,(1+P$4)^(-$B$5:$G$5)) -> 144791.51 | Q5: =SUMPRODUCT($B$26:$G$26,(1+Q$4)^(-$B$5:$G$5)) -> 52997.739 | ... AD5: =SUMPRODUCT($B$26:$G$26,(1+AD$4)^(-$B$5:$G$5)) -> -235983.06 | AF5: =B26*B6 -> -260000 | AG5: =C26*C6+AF5 -> -272367.58 | AH5: =D26*D6+AG5 -> -268108.75 | AI5: =E26*E6+AH5 -> -250820.85 | AJ5: =F26*F6+AI5 -> -226441.06 | AK5: =G26*G6+AJ5 -> -139467.55 | AM5: =IF(AND(AF5<0,AG5>=0),0+(-AF5)/(C26*C6),"") | AN5: =IF(AND(AG5<0,AH5>=0),1+(-AG5)/(D26*D6),"") | AO5: =IF(AND(AH5<0,AI5>=0),2+(-AH5)/(E26*E6),"") | AP5: =IF(AND(AI5<0,AJ5>=0),3+(-AI5)/(F26*F6),"") | AQ5: =IF(AND(AJ5<0,AK5>=0),4+(-AJ5)/(G26*G6),"")
A6: Factor (P/F, TMAR, t) | B6: =1/(1+Tasas!$C$10)^B5 -> 1 | C6: =1/(1+Tasas!$C$10)^C5 -> 0.86206897 | D6: =1/(1+Tasas!$C$10)^D5 -> 0.7431629 | E6: =1/(1+Tasas!$C$10)^E5 -> 0.64065767 | F6: =1/(1+Tasas!$C$10)^F5 -> 0.5522911 | G6: =1/(1+Tasas!$C$10)^G5 -> 0.47611302 | I6: Tienda Lima | J6: =SUMPRODUCT($B$42:$G$42,(1+J$4)^(-$B$5:$G$5)) -> -1088728.2 | K6: =SUMPRODUCT($B$42:$G$42,(1+K$4)^(-$B$5:$G$5)) -> -883297.3 | L6: =SUMPRODUCT($B$42:$G$42,(1+L$4)^(-$B$5:$G$5)) -> -738551.36 | M6: =SUMPRODUCT($B$42:$G$42,(1+M$4)^(-$B$5:$G$5)) -> -633191.48 | N6: =SUMPRODUCT($B$42:$G$42,(1+N$4)^(-$B$5:$G$5)) -> -554328.22 | O6: =SUMPRODUCT($B$42:$G$42,(1+O$4)^(-$B$5:$G$5)) -> -493852.89 | P6: =SUMPRODUCT($B$42:$G$42,(1+P$4)^(-$B$5:$G$5)) -> -446489.36 | Q6: =SUMPRODUCT($B$42:$G$42,(1+Q$4)^(-$B$5:$G$5)) -> -408701.45 | ... AD6: =SUMPRODUCT($B$42:$G$42,(1+AD$4)^(-$B$5:$G$5)) -> -230036.01 | AF6: =B42*B6 -> -130000 | AG6: =C42*C6+AF6 -> -208325.43 | AH6: =D42*D6+AG6 -> -258331.93 | AI6: =E42*E6+AH6 -> -285540.67 | AJ6: =F42*F6+AI6 -> -305544.65 | AK6: =G42*G6+AJ6 -> -310886.64 | AM6: =IF(AND(AF6<0,AG6>=0),0+(-AF6)/(C42*C6),"") | AN6: =IF(AND(AG6<0,AH6>=0),1+(-AG6)/(D42*D6),"") | AO6: =IF(AND(AH6<0,AI6>=0),2+(-AH6)/(E42*E6),"") | AP6: =IF(AND(AI6<0,AJ6>=0),3+(-AI6)/(F42*F6),"") | AQ6: =IF(AND(AJ6<0,AK6>=0),4+(-AJ6)/(G42*G6),"")
A7: Factor (P/F, TMAR antes de impuestos, t) | B7: =1/(1+Tasas!$C$13)^B5 -> 1 | C7: =1/(1+Tasas!$C$13)^C5 -> 0.8150289 | D7: =1/(1+Tasas!$C$13)^D5 -> 0.66427211 | E7: =1/(1+Tasas!$C$13)^E5 -> 0.54140097 | F7: =1/(1+Tasas!$C$13)^F5 -> 0.44125744 | G7: =1/(1+Tasas!$C$13)^G5 -> 0.35963756 | I7: Tienda Arequipa | J7: =SUMPRODUCT($B$57:$G$57,(1+J$4)^(-$B$5:$G$5)) -> -428299.34 | K7: =SUMPRODUCT($B$57:$G$57,(1+K$4)^(-$B$5:$G$5)) -> -372056.91 | L7: =SUMPRODUCT($B$57:$G$57,(1+L$4)^(-$B$5:$G$5)) -> -329382.66 | M7: =SUMPRODUCT($B$57:$G$57,(1+M$4)^(-$B$5:$G$5)) -> -296296.22 | N7: =SUMPRODUCT($B$57:$G$57,(1+N$4)^(-$B$5:$G$5)) -> -270147.41 | O7: =SUMPRODUCT($B$57:$G$57,(1+O$4)^(-$B$5:$G$5)) -> -249127 | P7: =SUMPRODUCT($B$57:$G$57,(1+P$4)^(-$B$5:$G$5)) -> -231971.33 | Q7: =SUMPRODUCT($B$57:$G$57,(1+Q$4)^(-$B$5:$G$5)) -> -217779.12 | ... AD7: =SUMPRODUCT($B$57:$G$57,(1+AD$4)^(-$B$5:$G$5)) -> -142125.9 | AF7: =B57*B6 -> -90000 | AG7: =C57*C6+AF7 -> -134126.29 | AH7: =D57*D6+AG7 -> -160404.35 | AI7: =E57*E6+AH7 -> -172117.49 | AJ7: =F57*F6+AI7 -> -179867.79 | AK7: =G57*G6+AJ7 -> -178455.17 | AM7: =IF(AND(AF7<0,AG7>=0),0+(-AF7)/(C57*C6),"") | AN7: =IF(AND(AG7<0,AH7>=0),1+(-AG7)/(D57*D6),"") | AO7: =IF(AND(AH7<0,AI7>=0),2+(-AH7)/(E57*E6),"") | AP7: =IF(AND(AI7<0,AJ7>=0),3+(-AI7)/(F57*F6),"") | AQ7: =IF(AND(AJ7<0,AK7>=0),4+(-AJ7)/(G57*G6),"")
A8: Fase 1 · Ventas online incrementales | C8: =Supuestos!$C$44*((1+Supuestos!$C$81)^1-1) -> 39960 | D8: =Supuestos!$C$44*((1+Supuestos!$C$81)^2-1) -> 83116.8 | E8: =Supuestos!$C$44*((1+Supuestos!$C$81)^3-1) -> 129726.14 | F8: =Supuestos!$C$44*((1+Supuestos!$C$81)^4-1) -> 180064.24 | G8: =Supuestos!$C$44*((1+Supuestos!$C$81)^5-1) -> 234429.37 | I8: Tiendas (Fase 2) | J8: =SUMPRODUCT($B$60:$G$60,(1+J$4)^(-$B$5:$G$5)) -> -1517027.5 | K8: =SUMPRODUCT($B$60:$G$60,(1+K$4)^(-$B$5:$G$5)) -> -1255354.2 | L8: =SUMPRODUCT($B$60:$G$60,(1+L$4)^(-$B$5:$G$5)) -> -1067934 | M8: =SUMPRODUCT($B$60:$G$60,(1+M$4)^(-$B$5:$G$5)) -> -929487.7 | N8: =SUMPRODUCT($B$60:$G$60,(1+N$4)^(-$B$5:$G$5)) -> -824475.63 | O8: =SUMPRODUCT($B$60:$G$60,(1+O$4)^(-$B$5:$G$5)) -> -742979.9 | P8: =SUMPRODUCT($B$60:$G$60,(1+P$4)^(-$B$5:$G$5)) -> -678460.69 | Q8: =SUMPRODUCT($B$60:$G$60,(1+Q$4)^(-$B$5:$G$5)) -> -626480.57 | ... AD8: =SUMPRODUCT($B$60:$G$60,(1+AD$4)^(-$B$5:$G$5)) -> -372161.91 | AF8: =B60*B6 -> -220000 | AG8: =C60*C6+AF8 -> -342451.72 | AH8: =D60*D6+AG8 -> -418736.28 | AI8: =E60*E6+AH8 -> -457658.16 | AJ8: =F60*F6+AI8 -> -485412.44 | AK8: =G60*G6+AJ8 -> -489341.8 | AM8: =IF(AND(AF8<0,AG8>=0),0+(-AF8)/(C60*C6),"") | AN8: =IF(AND(AG8<0,AH8>=0),1+(-AG8)/(D60*D6),"") | AO8: =IF(AND(AH8<0,AI8>=0),2+(-AH8)/(E60*E6),"") | AP8: =IF(AND(AI8<0,AJ8>=0),3+(-AI8)/(F60*F6),"") | AQ8: =IF(AND(AJ8<0,AK8>=0),4+(-AJ8)/(G60*G6),"")
A9: Fase 1 · Kg vendidos totales (actual + incremental) | C9: =Costos_Margenes!$D$24+C8/Supuestos!$C$31+C10/Supuestos!$C$35 -> 10951.575 | D9: =Costos_Margenes!$D$24+D8/Supuestos!$C$31+D10/Supuestos!$C$35 -> 11437.165 | E9: =Costos_Margenes!$D$24+E8/Supuestos!$C$31+E10/Supuestos!$C$35 -> 11943.554 | F9: =Costos_Margenes!$D$24+F8/Supuestos!$C$31+F10/Supuestos!$C$35 -> 12246.796 | G9: =Costos_Margenes!$D$24+G8/Supuestos!$C$31+G10/Supuestos!$C$35 -> 12574.297 | I9: Proyecto completo — económico | J9: =SUMPRODUCT($B$61:$G$61,(1+J$4)^(-$B$5:$G$5)) -> 1029722.7 | K9: =SUMPRODUCT($B$61:$G$61,(1+K$4)^(-$B$5:$G$5)) -> 396071.36 | L9: =SUMPRODUCT($B$61:$G$61,(1+L$4)^(-$B$5:$G$5)) -> 12684.279 | M9: =SUMPRODUCT($B$61:$G$61,(1+M$4)^(-$B$5:$G$5)) -> -225163.98 | N9: =SUMPRODUCT($B$61:$G$61,(1+N$4)^(-$B$5:$G$5)) -> -375501.99 | O9: =SUMPRODUCT($B$61:$G$61,(1+O$4)^(-$B$5:$G$5)) -> -471720.8 | P9: =SUMPRODUCT($B$61:$G$61,(1+P$4)^(-$B$5:$G$5)) -> -533669.18 | Q9: =SUMPRODUCT($B$61:$G$61,(1+Q$4)^(-$B$5:$G$5)) -> -573482.83 | ... AD9: =SUMPRODUCT($B$61:$G$61,(1+AD$4)^(-$B$5:$G$5)) -> -608144.97 | AF9: =B61*B6 -> -480000 | AG9: =C61*C6+AF9 -> -614819.31 | AH9: =D61*D6+AG9 -> -686845.03 | AI9: =E61*E6+AH9 -> -708479.01 | AJ9: =F61*F6+AI9 -> -711853.5 | AK9: =G61*G6+AJ9 -> -628809.35 | AM9: =IF(AND(AF9<0,AG9>=0),0+(-AF9)/(C61*C6),"") | AN9: =IF(AND(AG9<0,AH9>=0),1+(-AG9)/(D61*D6),"") | AO9: =IF(AND(AH9<0,AI9>=0),2+(-AH9)/(E61*E6),"") | AP9: =IF(AND(AI9<0,AJ9>=0),3+(-AI9)/(F61*F6),"") | AQ9: =IF(AND(AJ9<0,AK9>=0),4+(-AJ9)/(G61*G6),"")
A10: Fase 1 · Ventas B2B incrementales | C10: =Supuestos!$C$45*Supuestos!$C$82*MIN(1/3,1) -> 23125 | D10: =Supuestos!$C$45*Supuestos!$C$82*MIN(2/3,1) -> 46250 | E10: =Supuestos!$C$45*Supuestos!$C$82*MIN(3/3,1) -> 69375 | F10: =Supuestos!$C$45*Supuestos!$C$82*MIN(4/3,1) -> 69375 | G10: =Supuestos!$C$45*Supuestos!$C$82*MIN(5/3,1) -> 69375 | I10: Proyecto completo — financiero | J10: =SUMPRODUCT($B$70:$G$70,(1+J$4)^(-$B$5:$G$5)) -> -113093.83 | K10: =SUMPRODUCT($B$70:$G$70,(1+K$4)^(-$B$5:$G$5)) -> -472623.02 | L10: =SUMPRODUCT($B$70:$G$70,(1+L$4)^(-$B$5:$G$5)) -> -647605.82 | M10: =SUMPRODUCT($B$70:$G$70,(1+M$4)^(-$B$5:$G$5)) -> -723490.01 | N10: =SUMPRODUCT($B$70:$G$70,(1+N$4)^(-$B$5:$G$5)) -> -745542.16 | O10: =SUMPRODUCT($B$70:$G$70,(1+O$4)^(-$B$5:$G$5)) -> -738453.67 | P10: =SUMPRODUCT($B$70:$G$70,(1+P$4)^(-$B$5:$G$5)) -> -715989.57 | Q10: =SUMPRODUCT($B$70:$G$70,(1+Q$4)^(-$B$5:$G$5)) -> -685934.54 | ... AD10: =SUMPRODUCT($B$70:$G$70,(1+AD$4)^(-$B$5:$G$5)) -> -351383.9 | AF10: =B70*B6 -> 0 | AG10: =C70*C6+AF10 -> -286109.48 | AH10: =D70*D6+AG10 -> -490244.11 | AI10: =E70*E6+AH10 -> -627638.62 | AJ10: =F70*F6+AI10 -> -631013.11 | AK10: =G70*G6+AJ10 -> -547968.96 | AM10: =IF(AND(AF10<0,AG10>=0),0+(-AF10)/(C70*C6),"") | AN10: =IF(AND(AG10<0,AH10>=0),1+(-AG10)/(D70*D6),"") | AO10: =IF(AND(AH10<0,AI10>=0),2+(-AH10)/(E70*E6),"") | AP10: =IF(AND(AI10<0,AJ10>=0),3+(-AI10)/(F70*F6),"") | AQ10: =IF(AND(AJ10<0,AK10>=0),4+(-AJ10)/(G70*G6),"")
A11: Contribución online | C11: =C8*Costos_Margenes!$J$16 -> 19021.923 | D11: =D8*Costos_Margenes!$J$16 -> 39565.6 | E11: =E8*Costos_Margenes!$J$16 -> 61752.77 | F11: =F8*Costos_Margenes!$J$16 -> 85714.915 | G11: =G8*Costos_Margenes!$J$16 -> 111594.03 | I11: Solo Fase 1 — financiero | J11: =SUMPRODUCT($B$76:$G$76,(1+J$4)^(-$B$5:$G$5)) -> 1927724.6 | K11: =SUMPRODUCT($B$76:$G$76,(1+K$4)^(-$B$5:$G$5)) -> 1180882.8 | L11: =SUMPRODUCT($B$76:$G$76,(1+L$4)^(-$B$5:$G$5)) -> 722961.16 | M11: =SUMPRODUCT($B$76:$G$76,(1+M$4)^(-$B$5:$G$5)) -> 434397.12 | N11: =SUMPRODUCT($B$76:$G$76,(1+N$4)^(-$B$5:$G$5)) -> 248535.21 | O11: =SUMPRODUCT($B$76:$G$76,(1+O$4)^(-$B$5:$G$5)) -> 126778.79 | P11: =SUMPRODUCT($B$76:$G$76,(1+P$4)^(-$B$5:$G$5)) -> 46034.632 | Q11: =SUMPRODUCT($B$76:$G$76,(1+Q$4)^(-$B$5:$G$5)) -> -7913.6053 | ... AD11: =SUMPRODUCT($B$76:$G$76,(1+AD$4)^(-$B$5:$G$5)) -> -96904.145 | AF11: =B76*B6 -> 0 | AG11: =C76*C6+AF11 -> -94316.428 | AH11: =D76*D6+AG11 -> -161616.58 | AI11: =E76*E6+AH11 -> -207032.31 | AJ11: =F76*F6+AI11 -> -182652.51 | AK11: =G76*G6+AJ11 -> -95679 | AM11: =IF(AND(AF11<0,AG11>=0),0+(-AF11)/(C76*C6),"") | AN11: =IF(AND(AG11<0,AH11>=0),1+(-AG11)/(D76*D6),"") | AO11: =IF(AND(AH11<0,AI11>=0),2+(-AH11)/(E76*E6),"") | AP11: =IF(AND(AI11<0,AJ11>=0),3+(-AI11)/(F76*F6),"") | AQ11: =IF(AND(AJ11<0,AK11>=0),4+(-AJ11)/(G76*G6),"")
A12: Contribución B2B | C12: =C10*Costos_Margenes!$J$17 -> 7332.3171 | D12: =D10*Costos_Margenes!$J$17 -> 14664.634 | E12: =E10*Costos_Margenes!$J$17 -> 21996.951 | F12: =F10*Costos_Margenes!$J$17 -> 21996.951 | G12: =G10*Costos_Margenes!$J$17 -> 21996.951 | I12: Fase 1 — antes de impuestos (a TMAR antes de imp.) | J12: =SUMPRODUCT($B$27:$G$27,(1+J$4)^(-$B$5:$G$5)) -> 2728074.6 | K12: =SUMPRODUCT($B$27:$G$27,(1+K$4)^(-$B$5:$G$5)) -> 1763450 | L12: =SUMPRODUCT($B$27:$G$27,(1+L$4)^(-$B$5:$G$5)) -> 1149509.9 | M12: =SUMPRODUCT($B$27:$G$27,(1+M$4)^(-$B$5:$G$5)) -> 745614.36 | N12: =SUMPRODUCT($B$27:$G$27,(1+N$4)^(-$B$5:$G$5)) -> 472203.99 | O12: =SUMPRODUCT($B$27:$G$27,(1+O$4)^(-$B$5:$G$5)) -> 282463.39 | P12: =SUMPRODUCT($B$27:$G$27,(1+P$4)^(-$B$5:$G$5)) -> 147882.94 | Q12: =SUMPRODUCT($B$27:$G$27,(1+Q$4)^(-$B$5:$G$5)) -> 50569.133 | ... AD12: =SUMPRODUCT($B$27:$G$27,(1+AD$4)^(-$B$5:$G$5)) -> -248387.01 | AF12: =B27*B7 -> -260000 | AG12: =C27*C7+AF12 -> -286134.56 | AH12: =D27*D7+AG12 -> -288517.76 | AI12: =E27*E7+AH12 -> -274138.29 | AJ12: =F27*F7+AI12 -> -251679.22 | AK12: =G27*G7+AJ12 -> -180764.77 | AM12: =IF(AND(AF12<0,AG12>=0),0+(-AF12)/(C27*C7),"") | AN12: =IF(AND(AG12<0,AH12>=0),1+(-AG12)/(D27*D7),"") | AO12: =IF(AND(AH12<0,AI12>=0),2+(-AH12)/(E27*E7),"") | AP12: =IF(AND(AI12<0,AJ12>=0),3+(-AI12)/(F27*F7),"") | AQ12: =IF(AND(AJ12<0,AK12>=0),4+(-AJ12)/(G27*G7),"")
A13: Ahorros en costo (merma y empaque) | C13: =C9*(Supuestos!$C$58+Supuestos!$C$59) -> 13579.953 | D13: =D9*(Supuestos!$C$58+Supuestos!$C$59) -> 14182.085 | E13: =E9*(Supuestos!$C$58+Supuestos!$C$59) -> 14810.007 | F13: =F9*(Supuestos!$C$58+Supuestos!$C$59) -> 15186.027 | G13: =G9*(Supuestos!$C$58+Supuestos!$C$59) -> 15592.128 | I13: Proyecto completo — antes de impuestos (a TMAR antes de imp.) | J13: =SUMPRODUCT($B$62:$G$62,(1+J$4)^(-$B$5:$G$5)) -> -13659.975 | K13: =SUMPRODUCT($B$62:$G$62,(1+K$4)^(-$B$5:$G$5)) -> -409390.1 | L13: =SUMPRODUCT($B$62:$G$62,(1+L$4)^(-$B$5:$G$5)) -> -628700.26 | M13: =SUMPRODUCT($B$62:$G$62,(1+M$4)^(-$B$5:$G$5)) -> -749358.48 | N13: =SUMPRODUCT($B$62:$G$62,(1+N$4)^(-$B$5:$G$5)) -> -813424.92 | O13: =SUMPRODUCT($B$62:$G$62,(1+O$4)^(-$B$5:$G$5)) -> -844442.39 | P13: =SUMPRODUCT($B$62:$G$62,(1+P$4)^(-$B$5:$G$5)) -> -855968.4 | Q13: =SUMPRODUCT($B$62:$G$62,(1+Q$4)^(-$B$5:$G$5)) -> -855993.16 | ... AD13: =SUMPRODUCT($B$62:$G$62,(1+AD$4)^(-$B$5:$G$5)) -> -708365.16 | AF13: =B62*B7 -> -480000 | AG13: =C62*C7+AF13 -> -683647.85 | AH13: =D62*D7+AG13 -> -791783.17 | AI13: =E62*E7+AH13 -> -830515.14 | AJ13: =F62*F7+AI13 -> -846710.22 | AK13: =G62*G7+AJ13 -> -792195.24 | AM13: =IF(AND(AF13<0,AG13>=0),0+(-AF13)/(C62*C7),"") | AN13: =IF(AND(AG13<0,AH13>=0),1+(-AG13)/(D62*D7),"") | AO13: =IF(AND(AH13<0,AI13>=0),2+(-AH13)/(E62*E7),"") | AP13: =IF(AND(AI13<0,AJ13>=0),3+(-AI13)/(F62*F7),"") | AQ13: =IF(AND(AJ13<0,AK13>=0),4+(-AJ13)/(G62*G7),"")
A14: (−) Costos fijos incrementales | C14: =-Supuestos!$C$57 -> -72000 | D14: =-Supuestos!$C$57 -> -72000 | E14: =-Supuestos!$C$57 -> -72000 | F14: =-Supuestos!$C$57 -> -72000 | G14: =-Supuestos!$C$57 -> -72000
A15: EBITDA | C15: =SUM(C11:C14) -> -32065.807 | D15: =SUM(D11:D14) -> -3587.6813 | E15: =SUM(E11:E14) -> 26559.729 | F15: =SUM(F11:F14) -> 50897.893 | G15: =SUM(G11:G14) -> 77183.11
A16: (−) Depreciación y amortización | C16: =-(Supuestos!$C$52*Supuestos!$C$55+Supuestos!$C$53*Supuestos!$C$56) -> -28000 | D16: =-(Supuestos!$C$52*Supuestos!$C$55+Supuestos!$C$53*Supuestos!$C$56) -> -28000 | E16: =-(Supuestos!$C$52*Supuestos!$C$55+Supuestos!$C$53*Supuestos!$C$56) -> -28000 | F16: =-(Supuestos!$C$52*Supuestos!$C$55+Supuestos!$C$53*Supuestos!$C$56) -> -28000 | G16: =-(Supuestos!$C$52*Supuestos!$C$55+Supuestos!$C$53*Supuestos!$C$56) -> -28000
A17: Utilidad operativa (EBIT) | C17: =C15+C16 -> -60065.807 | D17: =D15+D16 -> -31587.681 | E17: =E15+E16 -> -1440.2711 | F17: =F15+F16 -> 22897.893 | G17: =G15+G16 -> 49183.11
A18: (−) Impuesto a la Renta (T × EBIT) | C18: =-C17*Supuestos!$C$7 -> 17719.413 | D18: =-D17*Supuestos!$C$7 -> 9318.366 | E18: =-E17*Supuestos!$C$7 -> 424.87998 | F18: =-F17*Supuestos!$C$7 -> -6754.8784 | G18: =-G17*Supuestos!$C$7 -> -14509.017
A19: Utilidad operativa después de impuestos | C19: =C17+C18 -> -42346.394 | D19: =D17+D18 -> -22269.315 | E19: =E17+E18 -> -1015.3911 | F19: =F17+F18 -> 16143.014 | G19: =G17+G18 -> 34674.093
A20: (+) Depreciación | C20: =-C16 -> 28000 | D20: =-D16 -> 28000 | E20: =-E16 -> 28000 | F20: =-F16 -> 28000 | G20: =-G16 -> 28000
A21: (−) Inversión fija y diferida | B21: =-(Supuestos!$C$52+Supuestos!$C$53) -> -230000
A22: Capital de trabajo requerido = MAX(inicial; 10 % de ventas) | B22: =Supuestos!$C$54 -> 30000 | C22: =MAX(Supuestos!$C$54,(C8+C10)*Supuestos!$C$9) -> 30000 | D22: =MAX(Supuestos!$C$54,(D8+D10)*Supuestos!$C$9) -> 30000 | E22: =MAX(Supuestos!$C$54,(E8+E10)*Supuestos!$C$9) -> 30000 | F22: =MAX(Supuestos!$C$54,(F8+F10)*Supuestos!$C$9) -> 30000 | G22: =MAX(Supuestos!$C$54,(G8+G10)*Supuestos!$C$9) -> 30380.437
A23: (−) Inversión en capital de trabajo (variación) | B23: =-B22 -> -30000 | C23: =-(C22-B22) -> 0 | D23: =-(D22-C22) -> 0 | E23: =-(E22-D22) -> 0 | F23: =-(F22-E22) -> 0 | G23: =-(G22-F22) -> -380.43744
A24: (+) Recuperación capital de trabajo | G24: =G22 -> 30380.437
A25: (+) Valor de rescate maquinaria (S) = valor en libros | G25: =Supuestos!$C$52*(1-5*Supuestos!$C$55) -> 90000
A26: FLUJO ECONÓMICO FASE 1 | B26: =SUM(B19:B25)-B22 -> -260000 | C26: =SUM(C19:C25)-C22 -> -14346.394 | D26: =SUM(D19:D25)-D22 -> 5730.6846 | E26: =SUM(E19:E25)-E22 -> 26984.609 | F26: =SUM(F19:F25)-F22 -> 44143.014 | G26: =SUM(G19:G25)-G22 -> 182674.09
A27: Flujo Fase 1 antes de impuestos | B27: =B26 -> -260000 | C27: =C26-C18 -> -32065.807 | D27: =D26-D18 -> -3587.6813 | E27: =E26-E18 -> 26559.729 | F27: =F26-F18 -> 50897.893 | G27: =G26-G18 -> 197183.11
A29: Fase 2 · tienda Lima
A30: Ventas tienda Lima | C30: =Supuestos!$C$83*Supuestos!F$71 -> 125000 | D30: =Supuestos!$C$83*Supuestos!G$71 -> 187500 | E30: =Supuestos!$C$83*Supuestos!H$71 -> 250000 | F30: =Supuestos!$C$83*Supuestos!I$71 -> 250000 | G30: =Supuestos!$C$83*Supuestos!J$71 -> 250000
A31: Contribución | C31: =C30*Supuestos!$C$68 -> 77500 | D31: =D30*Supuestos!$C$68 -> 116250 | E31: =E30*Supuestos!$C$68 -> 155000 | F31: =F30*Supuestos!$C$68 -> 155000 | G31: =G30*Supuestos!$C$68 -> 155000
A32: (−) Costos fijos (alquiler, personal) | C32: =-Supuestos!$C$69 -> -216000 | D32: =-Supuestos!$C$69 -> -216000 | E32: =-Supuestos!$C$69 -> -216000 | F32: =-Supuestos!$C$69 -> -216000 | G32: =-Supuestos!$C$69 -> -216000
A33: (−) Depreciación | C33: =-Supuestos!$C$62*Supuestos!$C$67 -> -23000 | D33: =-Supuestos!$C$62*Supuestos!$C$67 -> -23000 | E33: =-Supuestos!$C$62*Supuestos!$C$67 -> -23000 | F33: =-Supuestos!$C$62*Supuestos!$C$67 -> -23000 | G33: =-Supuestos!$C$62*Supuestos!$C$67 -> -23000
A34: Utilidad operativa (EBIT) | C34: =SUM(C31:C33) -> -161500 | D34: =SUM(D31:D33) -> -122750 | E34: =SUM(E31:E33) -> -84000 | F34: =SUM(F31:F33) -> -84000 | G34: =SUM(G31:G33) -> -84000
A35: (−) Impuesto a la Renta (T × EBIT) | C35: =-C34*Supuestos!$C$7 -> 47642.5 | D35: =-D34*Supuestos!$C$7 -> 36211.25 | E35: =-E34*Supuestos!$C$7 -> 24780 | F35: =-F34*Supuestos!$C$7 -> 24780 | G35: =-G34*Supuestos!$C$7 -> 24780
A36: Utilidad operativa después de impuestos | C36: =C34+C35 -> -113857.5 | D36: =D34+D35 -> -86538.75 | E36: =E34+E35 -> -59220 | F36: =F34+F35 -> -59220 | G36: =G34+G35 -> -59220
A37: (+) Depreciación | C37: =-C33 -> 23000 | D37: =-D33 -> 23000 | E37: =-E33 -> 23000 | F37: =-F33 -> 23000 | G37: =-G33 -> 23000
A38: (−) Inversión en acondicionamiento | B38: =-Supuestos!$C$62 -> -115000
A39: Capital de trabajo requerido = MAX(inicial; 10 % de ventas) | B39: =Supuestos!$C$64 -> 15000 | C39: =MAX(Supuestos!$C$64,C30*Supuestos!$C$9) -> 15000 | D39: =MAX(Supuestos!$C$64,D30*Supuestos!$C$9) -> 18750 | E39: =MAX(Supuestos!$C$64,E30*Supuestos!$C$9) -> 25000 | F39: =MAX(Supuestos!$C$64,F30*Supuestos!$C$9) -> 25000 | G39: =MAX(Supuestos!$C$64,G30*Supuestos!$C$9) -> 25000
A40: (−) Inversión en capital de trabajo (variación) | B40: =-B39 -> -15000 | C40: =-(C39-B39) -> 0 | D40: =-(D39-C39) -> -3750 | E40: =-(E39-D39) -> -6250 | F40: =-(F39-E39) -> 0 | G40: =-(G39-F39) -> 0
A41: (+) Recuperación capital de trabajo | G41: =G39 -> 25000
...

Sheet Flujo_Base
A1: Flujo de caja incremental — escenario Base
A2: Soles constantes de 2025, después de impuestos. VPN = Σ F_t × (P/F, TMAR, t).
I3: Auxiliar: VPN a distintas tasas (para interpolar la TIR) | AF3: Auxiliar: flujo descontado acumulado y año de recuperación
A4: Concepto | B4: Año 0 | C4: Año 1 | D4: Año 2 | E4: Año 3 | F4: Año 4 | G4: Año 5 | J4: -0.4 | K4: -0.35 | L4: -0.3 | M4: -0.25 | N4: -0.2 | O4: -0.15 | P4: -0.1 | Q4: -0.05 | R4: 0 | S4: 0.05 | T4: 0.1 | U4: 0.15 | V4: 0.2 | W4: 0.25 | X4: 0.3 | Y4: 0.35 | Z4: 0.4 | AA4: 0.45 | AB4: 0.5 | AC4: 0.55 | AD4: 0.6
A5: Periodo t | B5: 0 | C5: 1 | D5: 2 | E5: 3 | F5: 4 | G5: 5 | I5: Fase 1 | J5: =SUMPRODUCT($B$26:$G$26,(1+J$4)^(-$B$5:$G$5)) -> 6390049.8 | K5: =SUMPRODUCT($B$26:$G$26,(1+K$4)^(-$B$5:$G$5)) -> 4347479.1 | L5: =SUMPRODUCT($B$26:$G$26,(1+L$4)^(-$B$5:$G$5)) -> 3031954.1 | M5: =SUMPRODUCT($B$26:$G$26,(1+M$4)^(-$B$5:$G$5)) -> 2155477.6 | N5: =SUMPRODUCT($B$26:$G$26,(1+N$4)^(-$B$5:$G$5)) -> 1554098.6 | O5: =SUMPRODUCT($B$26:$G$26,(1+O$4)^(-$B$5:$G$5)) -> 1130709.9 | P5: =SUMPRODUCT($B$26:$G$26,(1+P$4)^(-$B$5:$G$5)) -> 825772.64 | Q5: =SUMPRODUCT($B$26:$G$26,(1+Q$4)^(-$B$5:$G$5)) -> 601654.78 | ... AD5: =SUMPRODUCT($B$26:$G$26,(1+AD$4)^(-$B$5:$G$5)) -> -148147.6 | AF5: =B26*B6 -> -260000 | AG5: =C26*C6+AF5 -> -251213.07 | AH5: =D26*D6+AG5 -> -207711.61 | AI5: =E26*E6+AH5 -> -145747.57 | AJ5: =F26*F6+AI5 -> -62699.558 | AK5: =G26*G6+AJ5 -> 117319.82 | AM5: =IF(AND(AF5<0,AG5>=0),0+(-AF5)/(C26*C6),"") | AN5: =IF(AND(AG5<0,AH5>=0),1+(-AG5)/(D26*D6),"") | AO5: =IF(AND(AH5<0,AI5>=0),2+(-AH5)/(E26*E6),"") | AP5: =IF(AND(AI5<0,AJ5>=0),3+(-AI5)/(F26*F6),"") | AQ5: =IF(AND(AJ5<0,AK5>=0),4+(-AJ5)/(G26*G6),"") -> 4.3482934
A6: Factor (P/F, TMAR, t) | B6: =1/(1+Tasas!$C$10)^B5 -> 1 | C6: =1/(1+Tasas!$C$10)^C5 -> 0.86206897 | D6: =1/(1+Tasas!$C$10)^D5 -> 0.7431629 | E6: =1/(1+Tasas!$C$10)^E5 -> 0.64065767 | F6: =1/(1+Tasas!$C$10)^F5 -> 0.5522911 | G6: =1/(1+Tasas!$C$10)^G5 -> 0.47611302 | I6: Tienda Lima | J6: =SUMPRODUCT($B$42:$G$42,(1+J$4)^(-$B$5:$G$5)) -> 904964.51 | K6: =SUMPRODUCT($B$42:$G$42,(1+K$4)^(-$B$5:$G$5)) -> 547778.4 | L6: =SUMPRODUCT($B$42:$G$42,(1+L$4)^(-$B$5:$G$5)) -> 321383.63 | M6: =SUMPRODUCT($B$42:$G$42,(1+M$4)^(-$B$5:$G$5)) -> 173403.21 | N6: =SUMPRODUCT($B$42:$G$42,(1+N$4)^(-$B$5:$G$5)) -> 74136.353 | O6: =SUMPRODUCT($B$42:$G$42,(1+O$4)^(-$B$5:$G$5)) -> 6072.9993 | P6: =SUMPRODUCT($B$42:$G$42,(1+P$4)^(-$B$5:$G$5)) -> -41464.449 | Q6: =SUMPRODUCT($B$42:$G$42,(1+Q$4)^(-$B$5:$G$5)) -> -75182.562 | ... AD6: =SUMPRODUCT($B$42:$G$42,(1+AD$4)^(-$B$5:$G$5)) -> -163125.61 | AF6: =B42*B6 -> -130000 | AG6: =C42*C6+AF6 -> -184375 | AH6: =D42*D6+AG6 -> -202482.16 | AI6: =E42*E6+AH6 -> -190088.64 | AJ6: =F42*F6+AI6 -> -173881.66 | AK6: =G42*G6+AJ6 -> -140865.6 | AM6: =IF(AND(AF6<0,AG6>=0),0+(-AF6)/(C42*C6),"") | AN6: =IF(AND(AG6<0,AH6>=0),1+(-AG6)/(D42*D6),"") | AO6: =IF(AND(AH6<0,AI6>=0),2+(-AH6)/(E42*E6),"") | AP6: =IF(AND(AI6<0,AJ6>=0),3+(-AI6)/(F42*F6),"") | AQ6: =IF(AND(AJ6<0,AK6>=0),4+(-AJ6)/(G42*G6),"")
A7: Factor (P/F, TMAR antes de impuestos, t) | B7: =1/(1+Tasas!$C$13)^B5 -> 1 | C7: =1/(1+Tasas!$C$13)^C5 -> 0.8150289 | D7: =1/(1+Tasas!$C$13)^D5 -> 0.66427211 | E7: =1/(1+Tasas!$C$13)^E5 -> 0.54140097 | F7: =1/(1+Tasas!$C$13)^F5 -> 0.44125744 | G7: =1/(1+Tasas!$C$13)^G5 -> 0.35963756 | I7: Tienda Arequipa | J7: =SUMPRODUCT($B$57:$G$57,(1+J$4)^(-$B$5:$G$5)) -> 1034112.3 | K7: =SUMPRODUCT($B$57:$G$57,(1+K$4)^(-$B$5:$G$5)) -> 677674.74 | L7: =SUMPRODUCT($B$57:$G$57,(1+L$4)^(-$B$5:$G$5)) -> 448107.09 | M7: =SUMPRODUCT($B$57:$G$57,(1+M$4)^(-$B$5:$G$5)) -> 295354.7 | N7: =SUMPRODUCT($B$57:$G$57,(1+N$4)^(-$B$5:$G$5)) -> 190830.78 | O7: =SUMPRODUCT($B$57:$G$57,(1+O$4)^(-$B$5:$G$5)) -> 117554.52 | P7: =SUMPRODUCT($B$57:$G$57,(1+P$4)^(-$B$5:$G$5)) -> 65088.094 | Q7: =SUMPRODUCT($B$57:$G$57,(1+Q$4)^(-$B$5:$G$5)) -> 26819.865 | ... AD7: =SUMPRODUCT($B$57:$G$57,(1+AD$4)^(-$B$5:$G$5)) -> -93136.392 | AF7: =B57*B6 -> -90000 | AG7: =C57*C6+AF7 -> -116850 | AH7: =D57*D6+AG7 -> -119487.49 | AI7: =E57*E6+AH7 -> -102158.98 | AJ7: =F57*F6+AI7 -> -83354.569 | AK7: =G57*G6+AJ7 -> -53812.709 | AM7: =IF(AND(AF7<0,AG7>=0),0+(-AF7)/(C57*C6),"") | AN7: =IF(AND(AG7<0,AH7>=0),1+(-AG7)/(D57*D6),"") | AO7: =IF(AND(AH7<0,AI7>=0),2+(-AH7)/(E57*E6),"") | AP7: =IF(AND(AI7<0,AJ7>=0),3+(-AI7)/(F57*F6),"") | AQ7: =IF(AND(AJ7<0,AK7>=0),4+(-AJ7)/(G57*G6),"")
A8: Fase 1 · Ventas online incrementales | C8: =Supuestos!$C$44*((1+Supuestos!$D$81)^1-1) -> 89910 | D8: =Supuestos!$C$44*((1+Supuestos!$D$81)^2-1) -> 196003.8 | E8: =Supuestos!$C$44*((1+Supuestos!$D$81)^3-1) -> 321194.48 | F8: =Supuestos!$C$44*((1+Supuestos!$D$81)^4-1) -> 468919.49 | G8: =Supuestos!$C$44*((1+Supuestos!$D$81)^5-1) -> 643235 | I8: Tiendas (Fase 2) | J8: =SUMPRODUCT($B$60:$G$60,(1+J$4)^(-$B$5:$G$5)) -> 1939076.8 | K8: =SUMPRODUCT($B$60:$G$60,(1+K$4)^(-$B$5:$G$5)) -> 1225453.1 | L8: =SUMPRODUCT($B$60:$G$60,(1+L$4)^(-$B$5:$G$5)) -> 769490.72 | M8: =SUMPRODUCT($B$60:$G$60,(1+M$4)^(-$B$5:$G$5)) -> 468757.91 | N8: =SUMPRODUCT($B$60:$G$60,(1+N$4)^(-$B$5:$G$5)) -> 264967.13 | O8: =SUMPRODUCT($B$60:$G$60,(1+O$4)^(-$B$5:$G$5)) -> 123627.52 | P8: =SUMPRODUCT($B$60:$G$60,(1+P$4)^(-$B$5:$G$5)) -> 23623.645 | Q8: =SUMPRODUCT($B$60:$G$60,(1+Q$4)^(-$B$5:$G$5)) -> -48362.697 | ... AD8: =SUMPRODUCT($B$60:$G$60,(1+AD$4)^(-$B$5:$G$5)) -> -256262 | AF8: =B60*B6 -> -220000 | AG8: =C60*C6+AF8 -> -301225 | AH8: =D60*D6+AG8 -> -321969.65 | AI8: =E60*E6+AH8 -> -292247.62 | AJ8: =F60*F6+AI8 -> -257236.23 | AK8: =G60*G6+AJ8 -> -194678.31 | AM8: =IF(AND(AF8<0,AG8>=0),0+(-AF8)/(C60*C6),"") | AN8: =IF(AND(AG8<0,AH8>=0),1+(-AG8)/(D60*D6),"") | AO8: =IF(AND(AH8<0,AI8>=0),2+(-AH8)/(E60*E6),"") | AP8: =IF(AND(AI8<0,AJ8>=0),3+(-AI8)/(F60*F6),"") | AQ8: =IF(AND(AJ8<0,AK8>=0),4+(-AJ8)/(G60*G6),"")
A9: Fase 1 · Kg vendidos totales (actual + incremental) | C9: =Costos_Margenes!$D$24+C8/Supuestos!$C$31+C10/Supuestos!$C$35 -> 11568.332 | D9: =Costos_Margenes!$D$24+D8/Supuestos!$C$31+D10/Supuestos!$C$35 -> 12748.915 | E9: =Costos_Margenes!$D$24+E8/Supuestos!$C$31+E10/Supuestos!$C$35 -> 14044.539 | F9: =Costos_Margenes!$D$24+F8/Supuestos!$C$31+F10/Supuestos!$C$35 -> 14934.449 | G9: =Costos_Margenes!$D$24+G8/Supuestos!$C$31+G10/Supuestos!$C$35 -> 15984.542 | I9: Proyecto completo — económico | J9: =SUMPRODUCT($B$61:$G$61,(1+J$4)^(-$B$5:$G$5)) -> 8329126.6 | K9: =SUMPRODUCT($B$61:$G$61,(1+K$4)^(-$B$5:$G$5)) -> 5572932.2 | L9: =SUMPRODUCT($B$61:$G$61,(1+L$4)^(-$B$5:$G$5)) -> 3801444.8 | M9: =SUMPRODUCT($B$61:$G$61,(1+M$4)^(-$B$5:$G$5)) -> 2624235.5 | N9: =SUMPRODUCT($B$61:$G$61,(1+N$4)^(-$B$5:$G$5)) -> 1819065.7 | O9: =SUMPRODUCT($B$61:$G$61,(1+O$4)^(-$B$5:$G$5)) -> 1254337.4 | P9: =SUMPRODUCT($B$61:$G$61,(1+P$4)^(-$B$5:$G$5)) -> 849396.28 | Q9: =SUMPRODUCT($B$61:$G$61,(1+Q$4)^(-$B$5:$G$5)) -> 553292.08 | ... AD9: =SUMPRODUCT($B$61:$G$61,(1+AD$4)^(-$B$5:$G$5)) -> -404409.6 | AF9: =B61*B6 -> -480000 | AG9: =C61*C6+AF9 -> -552438.07 | AH9: =D61*D6+AG9 -> -529681.25 | AI9: =E61*E6+AH9 -> -437995.19 | AJ9: =F61*F6+AI9 -> -319935.79 | AK9: =G61*G6+AJ9 -> -77358.488 | AM9: =IF(AND(AF9<0,AG9>=0),0+(-AF9)/(C61*C6),"") | AN9: =IF(AND(AG9<0,AH9>=0),1+(-AG9)/(D61*D6),"") | AO9: =IF(AND(AH9<0,AI9>=0),2+(-AH9)/(E61*E6),"") | AP9: =IF(AND(AI9<0,AJ9>=0),3+(-AI9)/(F61*F6),"") | AQ9: =IF(AND(AJ9<0,AK9>=0),4+(-AJ9)/(G61*G6),"")
A10: Fase 1 · Ventas B2B incrementales | C10: =Supuestos!$C$45*Supuestos!$D$82*MIN(1/3,1) -> 55500 | D10: =Supuestos!$C$45*Supuestos!$D$82*MIN(2/3,1) -> 111000 | E10: =Supuestos!$C$45*Supuestos!$D$82*MIN(3/3,1) -> 166500 | F10: =Supuestos!$C$45*Supuestos!$D$82*MIN(4/3,1) -> 166500 | G10: =Supuestos!$C$45*Supuestos!$D$82*MIN(5/3,1) -> 166500 | I10: Proyecto completo — financiero | J10: =SUMPRODUCT($B$70:$G$70,(1+J$4)^(-$B$5:$G$5)) -> 7186310.1 | K10: =SUMPRODUCT($B$70:$G$70,(1+K$4)^(-$B$5:$G$5)) -> 4704237.8 | L10: =SUMPRODUCT($B$70:$G$70,(1+L$4)^(-$B$5:$G$5)) -> 3141154.7 | M10: =SUMPRODUCT($B$70:$G$70,(1+M$4)^(-$B$5:$G$5)) -> 2125909.4 | N10: =SUMPRODUCT($B$70:$G$70,(1+N$4)^(-$B$5:$G$5)) -> 1449025.6 | O10: =SUMPRODUCT($B$70:$G$70,(1+O$4)^(-$B$5:$G$5)) -> 987604.54 | P10: =SUMPRODUCT($B$70:$G$70,(1+P$4)^(-$B$5:$G$5)) -> 667075.89 | Q10: =SUMPRODUCT($B$70:$G$70,(1+Q$4)^(-$B$5:$G$5)) -> 440840.37 | ... AD10: =SUMPRODUCT($B$70:$G$70,(1+AD$4)^(-$B$5:$G$5)) -> -147648.53 | AF10: =B70*B6 -> 0 | AG10: =C70*C6+AF10 -> -223728.25 | AH10: =D70*D6+AG10 -> -333080.33 | AI10: =E70*E6+AH10 -> -357154.8 | AJ10: =F70*F6+AI10 -> -239095.4 | AK10: =G70*G6+AJ10 -> 3481.9023 | AM10: =IF(AND(AF10<0,AG10>=0),0+(-AF10)/(C70*C6),"") | AN10: =IF(AND(AG10<0,AH10>=0),1+(-AG10)/(D70*D6),"") | AO10: =IF(AND(AH10<0,AI10>=0),2+(-AH10)/(E70*E6),"") | AP10: =IF(AND(AI10<0,AJ10>=0),3+(-AI10)/(F70*F6),"") | AQ10: =IF(AND(AJ10<0,AK10>=0),4+(-AJ10)/(G70*G6),"") -> 4.9856462
A11: Contribución online | C11: =C8*Costos_Margenes!$J$16 -> 42799.327 | D11: =D8*Costos_Margenes!$J$16 -> 93302.532 | E11: =E8*Costos_Margenes!$J$16 -> 152896.31 | F11: =F8*Costos_Margenes!$J$16 -> 223216.98 | G11: =G8*Costos_Margenes!$J$16 -> 306195.36 | I11: Solo Fase 1 — financiero | J11: =SUMPRODUCT($B$76:$G$76,(1+J$4)^(-$B$5:$G$5)) -> 5771024.2 | K11: =SUMPRODUCT($B$76:$G$76,(1+K$4)^(-$B$5:$G$5)) -> 3876936.3 | L11: =SUMPRODUCT($B$76:$G$76,(1+L$4)^(-$B$5:$G$5)) -> 2674296.9 | M11: =SUMPRODUCT($B$76:$G$76,(1+M$4)^(-$B$5:$G$5)) -> 1885551 | N11: =SUMPRODUCT($B$76:$G$76,(1+N$4)^(-$B$5:$G$5)) -> 1353660.2 | O11: =SUMPRODUCT($B$76:$G$76,(1+O$4)^(-$B$5:$G$5)) -> 986229.58 | P11: =SUMPRODUCT($B$76:$G$76,(1+P$4)^(-$B$5:$G$5)) -> 727015.76 | Q11: =SUMPRODUCT($B$76:$G$76,(1+Q$4)^(-$B$5:$G$5)) -> 540743.43 | ... AD11: =SUMPRODUCT($B$76:$G$76,(1+AD$4)^(-$B$5:$G$5)) -> -9068.6879 | AF11: =B76*B6 -> 0 | AG11: =C76*C6+AF11 -> -73161.915 | AH11: =D76*D6+AG11 -> -101219.44 | AI11: =E76*E6+AH11 -> -101959.03 | AJ11: =F76*F6+AI11 -> -18911.014 | AK11: =G76*G6+AJ11 -> 161108.37 | AM11: =IF(AND(AF11<0,AG11>=0),0+(-AF11)/(C76*C6),"") | AN11: =IF(AND(AG11<0,AH11>=0),1+(-AG11)/(D76*D6),"") | AO11: =IF(AND(AH11<0,AI11>=0),2+(-AH11)/(E76*E6),"") | AP11: =IF(AND(AI11<0,AJ11>=0),3+(-AI11)/(F76*F6),"") | AQ11: =IF(AND(AJ11<0,AK11>=0),4+(-AJ11)/(G76*G6),"") -> 4.1050499
